<?xml version="1.0"?>
<robot name="simple_robot">

  <!-- Base Link -->
  <link name="base_link">
    <visual>
      <geometry>
        <box size="0.4 0.3 0.1"/>
      </geometry>
      <material name="blue"/>
    </visual>
  </link>

  <!-- Left Wheel -->
  <link name="left_wheel"/>
  <joint name="left_wheel_joint" type="continuous">
    <parent link="base_link"/>
    <child link="left_wheel"/>
    <origin xyz="-0.15 0.15 0" rpy="0 0 0"/>
    <axis xyz="0 1 0"/>
  </joint>

  <!-- Right Wheel -->
  <link name="right_wheel"/>
  <joint name="right_wheel_joint" type="continuous">
    <parent link="base_link"/>
    <child link="right_wheel"/>
    <origin xyz="-0.15 -0.15 0" rpy="0 0 0"/>
    <axis xyz="0 1 0"/>
  </joint>

</robot>
